Workbook
Name CABLES1: CABLES1!$A$2:$K$19
Name CABLES2: CABLES1!$M$2:$V$19
Name CABLES3: #REF!
Name CABLES4: INSTALAÇÃO!$A$1:$J$18
Name CABLES4: MOTOR!$A$1:$J$18
Name CABLES4: #REF!
Name D: PRINCIPAL!$AW$2
Name MÉTODO: CABLES1!$A$22:$F$22
Name MOTOR: INSTALAÇÃO!$A$1:$H$38
Name MOTOR: MOTOR!$A$1:$H$38
Name NOME: CABLES1!$A$21:$B$38
Name PRINCIPAL: PRINCIPAL!$A$1:$AU$750
Name SOURCES: #REF!

Sheet PRINCIPAL
A1: Circuito | B1: Equipamento | D1: V | E1: φ | F1: Potência | I1: Efficiência | K1: Dist. | L1: Fator de Correção | Q1: Método Inst. | R1: Corrente (A) | U1: Demarradores (A) | Y1: Formação do Cabo | AG1: Eletroduto | AI1: Impedância (Ohm/km) | AK1: Capacidade de Tensão | AQ1: Isc (kA)
B2: De | C2: Para | F2: kW | G2: kVA | H2: CV | I2: F.P. | J2: h | K2: (m) | L2: Temp. | M2: Nº Circ. | N2: F.a | O2: F. t | P2: F. R | R2: Ib | S2: I'p | T2: Ip'd | U2: Disj. | V2: TC | W2: K | X2: R | Y2: n / fase | AA2: Seção | AB2: mm² | AC2: (A) Cabo | AD2: Isol. | AE2: n / fase | AF2: CA | AG2: n / Eletr. | AH2: ø | AI2: RCA | AJ2: XL | AK2: Máx. (%) | AL2: ΔV (%) | AM2: V/A.km | AN2: n / fase | AO2: CT | AP2: CK | AQ2: Isc (kA) | AR2: t (s) | AS2: Loc. | AT2: Cab. | AU2: CK
A3: - | B3: PN-4600002 | C3: PN-6210.03005 | D3: 480 | E3: 3 | G3: 150 | H3: =IFERROR(VLOOKUP(F3,MOTOR!A5:B38,2),) -> 0 | I3: =IF($F3>0,VLOOKUP($F3,MOTOR,7,FALSE),1) -> 1 | J3: =IF($F3>0,VLOOKUP($F3,MOTOR,6,FALSE),1) -> 1 | K3: 320 | L3: 40 | M3: 6 | N3: =IFERROR( IF(OR(Q3="E",Q3="F"), INDEX('Fatores de correção'!$B$24:$M$27,MATCH("Métodos E e F",'Fatores de correção'!$A$24:$A$27,0),MATCH(M3,'Fatores de correção'!$B$23:$M$23,0)), IF(OR(Q3="B2",Q3="B1",Q3="D"), INDEX('Fatores de correção'!$B$24:$M$27,MATCH("Métodos A a F",'Fatores de correção'!$A$24:$A$27,0),MATCH(M3,'Fatores de correção'!$B$23:$M$23,0)), "") ), "Valor não encontrado") -> 0.73 | O3: =IFERROR( IF(OR(Q3="B1",Q3="B2",Q3="E",Q3="F"), IF(AD3="PVC",VLOOKUP(L3,'Fatores de correção'!A5:C19,2,FALSE),VLOOKUP(L3,'Fatores de correção'!A5:C19,3,FALSE)), IF(Q3="D", IF(AD3="PVC",VLOOKUP(L3,'Fatores de correção'!A5:E19,4,FALSE),VLOOKUP(L3,'Fatores de correção'!A5:E19,5,FALSE)), "Método inválido") ), "Valor não encontrado") -> 0.91 | P3: =IF(G3>0,1,IF(1/(N3*O3)<1.25,1.25,1)) -> 1 | Q3: F | R3: =IFERROR(IF(G3=0,IF(E3=3,F3*1000/(D3*SQRT(3)*I3*J3),IF(OR(E3=2,E3=1),F3*1000/(D3*I3*J3),"FASES ERRÓNEAS")),IF(E3=3,G3*1000/(D3*J3*SQRT(3)),IF(OR(E3=2,E3=1),G3*1000/(D3*J3),"FASES ERRÓNEAS"))),"FROM") -> 180.42196 | S3: =IFERROR(IF(1/(N3*O3)<P3,R3*P3,1/(N3*O3)*R3),"FROM") -> 271.59711 | T3: =IFERROR(S3/Y3,0) -> 271.59711 | U3: =IF(R3="FROM","-",IF(AND(F3=0,G3=0),"-",IF(F3=0,IF(R3<CABLES1!$BL$5,CABLES1!$BL$5,IF(LOOKUP(R3*1.05,CABLES1!$BL$4:$BL$30,CABLES1!$BL$5:$BL$30)<=AC3*Y3,LOOKUP(R3*1.05,CABLES1!$BL$4:$BL$30,CABLES1!$BL$5:$BL$30),"Erro")),IF(D3=440,VLOOKUP(F3,MOTOR!$I$5:$L$38,2,FALSE),IF(D3=380,VLOOKUP(F3,MOTOR!$M$5:$P$38,2,FALSE),IF(D3=220,VLOOKUP(F3,MOTOR!$Q$5:$T$38,2,FALSE),"Tensão")))))) -> 200 | V3: =IFERROR(IF(AND(F3=0,G3=0),"-",IF(R3<CABLES1!$BM$5,CABLES1!$BM$5,LOOKUP(R3*1.2,CABLES1!$BM$4:$BM$21,CABLES1!$BM$5:$BM$21))),"-") -> 250 | W3: =IFERROR(IF(R3="FROM","-",IF(D3=440,VLOOKUP(F3,MOTOR!$I$5:$L$38,3,FALSE),IF(D3=380,VLOOKUP(F3,MOTOR!$M$5:$P$38,3,FALSE),IF(D3=220,VLOOKUP(F3,MOTOR!$Q$5:$T$38,3,FALSE),"-")))),"-") -> - | X3: =IFERROR(IF(R3="FROM","-",IF(D3=440,VLOOKUP(F3,MOTOR!$I$5:$L$38,4,FALSE),IF(D3=380,VLOOKUP(F3,MOTOR!$M$5:$P$38,4,FALSE),IF(D3=220,VLOOKUP(F3,MOTOR!$Q$5:$T$38,4,FALSE),"-")))),"-") -> - | Y3: =IFERROR(IF(AE3>AN3,AE3,AN3),"-") -> 1 | Z3: x | AA3: 3x1 | AB3: =IFERROR(IF(AE3>AN3,AF3,MAX(AF3,AO3)),"-") -> 240 | AC3: {=IF(AD3="HEPR",IF(E3=3,INDEX(_xlfn._xlws.FILTER(Cabos!$D:$D,Cabos!$A:$A=Q3),MATCH(AB3,_xlfn._xlws.FILTER(Cabos!$B:$B,Cabos!$A:$A=Q3),0)),INDEX(_xlfn._xlws.FILTER(Cabos!$C:$C,Cabos!$A:$A=Q3),MATCH(AB3,_xlfn._xlws.FILTER(Cabos!$B:$B,Cabos!$A:$A=Q3),0))),IF(AD3="PVC",IF(E3=3,INDEX(_xlfn._xlws.FILTER(Cabos!$F:$F,Cabos!$A:$A=Q3),MATCH(AB3,_xlfn._xlws.FILTER(Cabos!$B:$B,Cabos!$A:$A=Q3),0)),INDEX(_xlfn._xlws.FILTER(Cabos!$E:$E,Cabos!$A:$A=Q3),MATCH(AB3,_xlfn._xlws.FILTER(Cabos!$B:$B,Cabos!$A:$A=Q3),0))),"Tipo de isolação inválido"))} -> 607 | AD3: HEPR | AE3: {=IF(S3=0,1,CEILING(S3/INDEX(_xlfn._xlws.FILTER(IF(AD3="HEPR",IF(E3=3,Cabos!$D:$D,Cabos!$C:$C),IF(E3=3,Cabos!$F:$F,Cabos!$E:$E)),Cabos!$A:$A=Q3),MATCH(240,_xlfn._xlws.FILTER(Cabos!$B:$B,Cabos!$A:$A=Q3),0)),1))} -> 1 | AF3: {=IF(AD3="HEPR",IF(E3=3,_xlfn.XLOOKUP(S3/AE3,_xlfn._xlws.FILTER(Cabos!$D:$D,Cabos!$A:$A=Q3,""),_xlfn._xlws.FILTER(Cabos!$B:$B,Cabos!$A:$A=Q3,""),"Não encontrado",1),_xlfn.XLOOKUP(S3/AE3,_xlfn._xlws.FILTER(Cabos!$C:$C,Cabos!$A:$A=Q3,""),_xlfn._xlws.FILTER(Cabos!$B:$B,Cabos!$A:$A=Q3,""),"Não encontrado",1)),IF(E3=3,_xlfn.XLOOKUP(S3/AE3,_xlfn._xlws.FILTER(Cabos!$F:$F,Cabos!$A:$A=Q3,""),_xlfn._xlws.FILTER(Cabos!$B:$B,Cabos!$A:$A=Q3,""),"Não encontrado",1),_xlfn.XLOOKUP(S3/AE3,_xlfn._xlws.FILTER(Cabos!$E:$E,Cabos!$A:$A=Q3,""),_xlfn._xlws.FILTER(Cabos!$B:$B,Cabos!$A:$A=Q3,""),"Não encontrado",1)))} -> 95 | AG3: =Y3&" x" -> 1 x | AH3: =IFERROR(LOOKUP(IF(IF(AA3="3x1",3,IF(AA3="4x1",4,1))=1,SQRT(((((INDEX(CABLES1!$D$45:$I$60,MATCH(AB3,CABLES1!$B$45:$B$60,0),MATCH(AA3,CABLES1!$D$44:$I$44,0))/2)^2)*3.1416)*IF(AA3="3x1",3,IF(AA3="4x1",4,1))/0.53)/3.1416)*2,SQRT(((((INDEX(CABLES1!$D$45:$I$60,MATCH(AB3,CABLES1!$B$45:$B$60,0),MATCH(AA3,CABLES1!$D$44:$I$44,0))/2)^2)*3.1416)*IF(AA3="3x1",3,IF(AA3="4x1",4,1))/0.4)/3.1416)*2),CABLES1!$N$23:$N$36,CABLES1!$M$24:$M$36),"-") -> 3.1/2" | AI3: =IF(AD3="PVC",IF(OR(AA3="1x3",AA3="1x3 BL",AA3="1x4"),INDEX(Resistência!$B$2:$I$21,MATCH(AO3,Resistência!$A$2:$A$21,0),7),IF(OR(AA3="3x1",AA3="4x1"),INDEX(Resistência!$B$2:$I$21,MATCH(AO3,Resistência!$A$2:$A$21,0),5),IF(AA3="1x2",INDEX(Resistência!$B$2:$I$21,MATCH(AO3,Resistência!$A$2:$A$21,0),3),IF(AA3="2x1",INDEX(Resistência!$B$2:$I$21,MATCH(AB3,Resistência!$A$2:$A$21,0),1),"Não encontrado")))),IF(OR(AA3="1x3",AA3="1x3 BL",AA3="1x4"),INDEX(Resistência!$B$25:$I$44,MATCH(AB3,Resistência!$A$25:$A$44,0),7),IF(OR(AA3="3x1",AA3="4x1"),INDEX(Resistência!$B$25:$I$44,MATCH(AB3,Resistência!$A$25:$A$44,0),5),IF(AA3="1x2",INDEX(Resistência!$B$25:$I$44,MATCH(AB3,Resistência!$A$25:$A$44,0),3),IF(AA3="2x1",INDEX(Resistência!$B$25:$I$44,MATCH(AB3,Resistência!$A$25:$A$44,0),1),"Não encontrado"))))) -> 0.1 | AJ3: =IF(AD3="PVC",IF(OR(AA3="1x3",AA3="1x3 BL",AA3="1x4"),INDEX(Resistência!$B$2:$I$21,MATCH(AB3,Resistência!$A$2:$A$21,0),8),IF(OR(AA3="3x1",AA3="4x1"),INDEX(Resistência!$B$2:$I$21,MATCH(AB3,Resistência!$A$2:$A$21,0),6),IF(AA3="1x2",INDEX(Resistência!$B$2:$I$21,MATCH(AB3,Resistência!$A$2:$A$21,0),4),IF(AA3="2x1",INDEX(Resistência!$B$2:$I$21,MATCH(AB3,Resistência!$A$2:$A$21,0),2),"Não encontrado")))),IF(AD3="HEPR",IF(OR(AA3="1x3",AA3="1x3 BL",AA3="1x4"),INDEX(Resistência!$B$25:$I$44,MATCH(AB3,Resistência!$A$25:$A$44,0),8),IF(OR(AA3="3x1",AA3="4x1"),INDEX(Resistência!$B$25:$I$44,MATCH(AB3,Resistência!$A$25:$A$44,0),6),IF(AA3="1x2",INDEX(Resistência!$B$25:$I$44,MATCH(AB3,Resistência!$A$25:$A$44,0),4),IF(AA3="2x1",INDEX(Resistência!$B$25:$I$44,MATCH(AB3,Resistência!$A$25:$A$44,0),2),"Não encontrado")))))) -> 0.09 | AK3: 3 | AL3: =IFERROR((IFERROR(IF(E3=3,(SQRT(3)*R3*(K3/1000)*SQRT(AI3^2+AJ3^2))/AE3,(2*R3*(K3/1000)*SQRT(AI3^2+AJ3^2))/AE3),"Erro")/D3)*100,"–") -> 2.8028383 | AM3: =IFERROR(((D3*(AK3/100))/((R3/INT(AN3))*(K3/1000))),"-") -> 0.24941532 | AN3: =INT(IFERROR(IF(OR(AA3="1x2",AA3="1x3",AA3="1x3 BL",AA3="1x4"),CABLES1!$BG$5/((D3*(AK3/100))/((R3)*(K3/1000)))+1,CABLES1!$BI$5/((D3*(AK3/100))/((R3)*(K3/1000)))+1),"-")) -> 1 | AO3: {=IF(AD3="HEPR",INDEX(tensão!$A$6:$A$22,IFERROR(MATCH(AM3,IF(AF3<150,IF(AA3="2x1",tensão!$C$6:$C$22,IF(AA3="1x2",tensão!$E$6:$E$22,IF(AA3="3x1",tensão!$G$6:$G$22,IF(AA3="1x3",tensão!$I$6:$I$22,IF(AA3="1x3 BL",tensão!$I$6:$I$22,IF(AA3="1x4",tensão!$I$6:$I$22,IF(AA3="4x1",tensão!$G$6:$G$22,"Não encontrado"))))))),IF(AA3="2x1",tensão!$B$6:$B$22,IF(AA3="1x2",tensão!$D$6:$D$22,IF(AA3="3x1",tensão!$F$6:$F$22,IF(AA3="1x3",tensão!$H$6:$H$22,IF(AA3="1x3 BL",tensão!$H$6:$H$22,IF(AA3="1x4",tensão!$H$6:$H$22,IF(AA3="4x1",tensão!$F$6:$F$22,"Não encontrado")))))))),-1)+1,1)),IF(AD3="PVC",INDEX(tensão!$A$29:$A$45,IFERROR(MATCH(AM3,IF(AF3<150,IF(AA3="2x1",tensão!$C$29:$C$45,IF(AA3="1x2",tensão!$E$29:$E$45,IF(AA3="3x1",tensão!$G$29:$G$45,IF(AA3="1x3",tensão!$I$29:$I$45,IF(AA3="1x3 BL",tensão!$I$29:$I$45,IF(AA3="1x4",tensão!$I$29:$I$45,IF(AA3="4x1",tensão!$G$29:$G$45,"Não encontrado"))))))),IF(AA3="2x1",tensão!$B$29:$B$45,IF(AA3="1x2",tensão!$D$29:$D$45,IF(AA3="3x1",tensão!$F$29:$F$45,IF(AA3="1x3",tensão!$H$29:$H$45,IF(AA3="1x3 BL",tensão!$H$29:$H$45,IF(AA3="1x4",tensão!$H$29:$H$45,IF(AA3="4x1",tensão!$F$29:$F$45,"Não encontrado")))))))),-1)+1,1)),"Tipo de isolação inválido"))} -> 240 | AP3: =IF(AL3<=AK3,"OK","X") -> OK | AQ3: 80 | AR3: 0.05 | AS3: =IFERROR(D3/(SQRT(3)*(K3*SQRT((AI3^2)+(AJ3^2))+D3/(SQRT(3)*AQ3))),"FROM") -> 5.9577334 | AT3: =IFERROR(142*AB3*IF(Y3="",1,Y3)/SQRT(AR3)/1000,"-") -> 152.41039 | AU3: =IF(AS3<=AT3,"OK","X") -> OK

Sheet Cabos
A1: Método de Instalação | B1: Seção (mm2) | C1: Isolação HEPR | E1: Isolação PVC | H1: Tabela 3 - Seção Mínima do Condutor Neutro | M1: Tabela 4 - Seção Mínima do Condutor de Proteção (PE)
C2: Imax (A) 2 Condutores | D2: Imax (A) 3 Condutores | E2: Imax (A) 2 Condutores | F2: Imax (A) 3 Condutores | H2: Seção dos condutores de fase (mm²) | I2: Seção do condutor neutro (mm²) | M2: Seção dos condutores de fase, S mm² | N2: Seção mínima do condutor de proteção correspondente mm²
A3: B2 | B3: 2.5 | C3: 30 | D3: 26 | E3: 23 | F3: 20 | H3: S ≤ 25 | I3: S | M3: S ≤ 16 | N3: S
A4: B2 | B4: 4 | C4: 35 | D4: 45 | E4: 30 | F4: 27 | H4: 35 | I4: 25 | M4: 16 < S ≤ 35 | N4: 16 (1)
A5: B2 | B5: 6 | C5: 44 | D5: 58 | E5: 38 | F5: 34 | H5: 50 | I5: 25 | M5: S > 35 | N5: S/2 (1)
A6: B2 | B6: 10 | C6: 59 | D6: 60 | E6: 52 | F6: 46 | H6: 70 | I6: 35
A7: B2 | B7: 16 | C7: 91 | D7: 80 | E7: 69 | F7: 62 | H7: 95 | I7: 50
A8: B2 | B8: 25 | C8: 119 | D8: 105 | E8: 90 | F8: 80 | H8: 120 | I8: 70
A9: B2 | B9: 35 | C9: 146 | D9: 128 | E9: 111 | F9: 99 | H9: 150 | I9: 70
A10: B2 | B10: 50 | C10: 175 | D10: 154 | E10: 133 | F10: 118 | H10: 185 | I10: 95
A11: B2 | B11: 70 | C11: 221 | D11: 194 | E11: 168 | F11: 149 | H11: 240 | I11: 120
A12: B2 | B12: 95 | C12: 255 | D12: 233 | E12: 201 | F12: 179 | H12: 300 | I12: 150
A13: B2 | B13: 120 | C13: 305 | D13: 268 | E13: 232 | F13: 206 | H13: 400 | I13: 185
A14: B2 | B14: 150 | C14: 349 | D14: 307 | E14: 265 | F14: 236
A15: B2 | B15: 185 | C15: 395 | D15: 348 | E15: 300 | F15: 268
A16: B2 | B16: 240 | C16: 452 | D16: 407 | E16: 351 | F16: 313
A17: B2 | B17: 300 | C17: 529 | D17: 465 | E17: 401 | F17: 358
A19: D | B19: 2.5 | C19: 34 | D19: 29 | E19: 29 | F19: 24
A20: D | B20: 4 | C20: 44 | D20: 37 | E20: 38 | F20: 31
A21: D | B21: 6 | C21: 56 | D21: 46 | E21: 47 | F21: 39
A22: D | B22: 10 | C22: 73 | D22: 61 | E22: 63 | F22: 52
A23: D | B23: 16 | C23: 95 | D23: 79 | E23: 81 | F23: 67
A24: D | B24: 25 | C24: 121 | D24: 101 | E24: 104 | F24: 86
A25: D | B25: 35 | C25: 146 | D25: 122 | E25: 125 | F25: 103
A26: D | B26: 50 | C26: 173 | D26: 144 | E26: 148 | F26: 122
... A81: B1 | B81: 300 | C81: 628 | D81: 553 | E81: 477 | F81: 426

Sheet Resistência
A1: Tabela 31 - Resistências Elétricas e Reatâncias Indutivas - Sintenax Flex (cobre) - PVC
A2: Seção nominal (mm²) | B2: 2x1 | D2: 1x2 | F2: 3x1 | H2: 1x3
B3: Rca (Ω/km) | C3: XL (Ω/km) | D3: Rca (Ω/km) | E3: XL (Ω/km) | F3: Rca (Ω/km) | G3: XL (Ω/km) | H3: Rca (Ω/km) | I3: XL (Ω/km)
A4: 1.5 | B4: 15.9 | C4: 0.16 | D4: 15.9 | E4: 0.13 | F4: 15.9 | G4: 0.16 | H4: 15.9 | I4: 0.13
A5: 2.5 | B5: 9.55 | C5: 0.15 | D5: 9.55 | E5: 0.12 | F5: 9.55 | G5: 0.15 | H5: 9.55 | I5: 0.12
A6: 4 | B6: 5.92 | C6: 0.15 | D6: 5.92 | E6: 0.12 | F6: 5.92 | G6: 0.15 | H6: 5.92 | I6: 0.12
A7: 6 | B7: 3.95 | C7: 0.13 | D7: 3.95 | E7: 0.11 | F7: 3.95 | G7: 0.13 | H7: 3.95 | I7: 0.11
A8: 10 | B8: 2.29 | C8: 0.12 | D8: 2.29 | E8: 0.1 | F8: 2.29 | G8: 0.12 | H8: 2.29 | I8: 0.1
A9: 16 | B9: 1.45 | C9: 0.11 | D9: 1.45 | E9: 0.09 | F9: 1.45 | G9: 0.11 | H9: 1.45 | I9: 0.09
A10: 25 | B10: 0.93 | C10: 0.11 | D10: 0.93 | E10: 0.1 | F10: 0.93 | G10: 0.11 | H10: 0.93 | I10: 0.1
A11: 35 | B11: 0.66 | C11: 0.1 | D11: 0.66 | E11: 0.09 | F11: 0.66 | G11: 0.1 | H11: 0.66 | I11: 0.09
A12: 50 | B12: 0.46 | C12: 0.1 | D12: 0.46 | E12: 0.09 | F12: 0.46 | G12: 0.1 | H12: 0.46 | I12: 0.09
A13: 70 | B13: 0.33 | C13: 0.1 | D13: 0.33 | E13: 0.09 | F13: 0.33 | G13: 0.1 | H13: 0.33 | I13: 0.09
A14: 95 | B14: 0.25 | C14: 0.1 | D14: 0.25 | E14: 0.09 | F14: 0.25 | G14: 0.1 | H14: 0.25 | I14: 0.09
A15: 120 | B15: 0.19 | C15: 0.1 | D15: 0.19 | E15: 0.09 | F15: 0.2 | G15: 0.1 | H15: 0.2 | I15: 0.09
... A18: 240 | B18: 0.1 | C18: 0.1 | D18: 0.1 | E18: 0.09 | F18: 0.1 | G18: 0.1 | H18: 0.1 | I18: 0.09
A19: 300 | B19: 0.08 | C19: 0.09 | D19: - | E19: - | F19: 0.08 | G19: 0.09 | H19: - | I19: -
A20: 400 | B20: 0.06 | C20: 0.09 | D20: - | E20: - | F20: 0.06 | G20: 0.09 | H20: - | I20: -
A21: 500 | B21: 0.05 | C21: 0.09 | D21: - | E21: - | F21: 0.05 | G21: 0.09 | H21: - | I21: -
A24: Tabela 32 - Resistências Elétricas e Reatâncias Indutivas - GSette Easy (cobre) e Afumex Flex (cobre) - HEPR
A25: Seção nominal (mm²) | B25: 2x1 | D25: 1x2 | F25: 3x1 | H25: 1x3
B26: Rca (Ω/km) | C26: XL (Ω/km) | D26: Rca (Ω/km) | E26: XL (Ω/km) | F26: Rca (Ω/km) | G26: XL (Ω/km) | H26: Rca (Ω/km) | I26: XL (Ω/km)
A27: 1.5 | B27: 15.4 | C27: 0.15 | D27: 15.4 | E27: 0.12 | F27: 15.4 | G27: 0.15 | H27: 15.4 | I27: 0.12
A28: 2.5 | B28: 9.45 | C28: 0.14 | D28: 9.45 | E28: 0.11 | F28: 9.45 | G28: 0.14 | H28: 9.45 | I28: 0.11
A29: 4 | B29: 5.88 | C29: 0.13 | D29: 5.88 | E29: 0.1 | F29: 5.88 | G29: 0.13 | H29: 5.88 | I29: 0.1
A30: 6 | B30: 3.93 | C30: 0.12 | D30: 3.93 | E30: 0.1 | F30: 3.93 | G30: 0.12 | H30: 3.93 | I30: 0.1
A31: 10 | B31: 2.33 | C31: 0.12 | D31: 2.33 | E31: 0.1 | F31: 2.33 | G31: 0.12 | H31: 2.33 | I31: 0.1
A32: 16 | B32: 1.47 | C32: 0.11 | D32: 1.47 | E32: 0.09 | F32: 1.47 | G32: 0.11 | H32: 1.47 | I32: 0.09
A33: 25 | B33: 0.93 | C33: 0.11 | D33: 0.93 | E33: 0.09 | F33: 0.93 | G33: 0.11 | H33: 0.93 | I33: 0.09
A34: 35 | B34: 0.67 | C34: 0.11 | D34: 0.67 | E34: 0.09 | F34: 0.67 | G34: 0.11 | H34: 0.67 | I34: 0.09
A35: 50 | B35: 0.49 | C35: 0.1 | D35: 0.49 | E35: 0.09 | F35: 0.49 | G35: 0.1 | H35: 0.49 | I35: 0.09
A36: 70 | B36: 0.34 | C36: 0.1 | D36: 0.34 | E36: 0.09 | F36: 0.34 | G36: 0.1 | H36: 0.34 | I36: 0.09
A37: 95 | B37: 0.25 | C37: 0.1 | D37: 0.25 | E37: 0.08 | F37: 0.25 | G37: 0.1 | H37: 0.25 | I37: 0.08
A38: 120 | B38: 0.2 | C38: 0.1 | D38: 0.2 | E38: 0.08 | F38: 0.2 | G38: 0.1 | H38: 0.2 | I38: 0.08
... A41: 240 | B41: 0.1 | C41: 0.09 | D41: 0.1 | E41: 0.08 | F41: 0.1 | G41: 0.09 | H41: 0.1 | I41: 0.08
A42: 300 | B42: 0.08 | C42: 0.09 | D42: - | E42: - | F42: 0.08 | G42: 0.09 | H42: - | I42: -
A43: 400 | B43: 0.07 | C43: 0.09 | D43: - | E43: - | F43: 0.07 | G43: 0.09 | H43: - | I43: -
A44: 500 | B44: 0.05 | C44: 0.09 | D44: - | E44: - | F44: 0.05 | G44: 0.09 | H44: - | I44: -
A46: Frequência: 60 Hz • Rca: Resistência elétrica máxima do condutor em corrente alternada na temperatura de operação • XL: Reatância Indutiva
A48: Tabela 37 - Valores de k
...

Sheet tensão
A1: Tabela 23 - Queda de Tensão - GSette Easy (cobre) e Afumex Flex (cobre)
A2: Seção nominal (mm²) | B2: 2x1 | D2: 1x2 | F2: 3x1 | H2: 1x3
B3: FP=0,8 | C3: FP=0,95 | D3: FP=0,8 | E3: FP=0,95 | F3: FP=0,8 | G3: FP=0,95 | H3: FP=0,8 | I3: FP=0,95
B4: (V/A.km) | C4: (V/A.km) | D4: (V/A.km) | E4: (V/A.km) | F4: (V/A.km) | G4: (V/A.km) | H4: (V/A.km) | I4: (V/A.km)
A5: 1.5 | B5: 27.38 | C5: 32.4 | D5: 27.34 | E5: 32.37 | F5: 23.69 | G5: 28.02 | H5: 23.65 | I5: 28
A6: 2.5 | B6: 16.46 | C6: 19.43 | D6: 16.42 | E6: 19.41 | F6: 14.27 | G6: 16.84 | H6: 14.23 | I6: 16.82
A7: 4 | B7: 10.26 | C7: 12.07 | D7: 10.22 | E7: 12.05 | F7: 8.87 | G7: 10.44 | H7: 8.84 | I7: 10.43
A8: 6 | B8: 6.89 | C8: 8.08 | D8: 6.86 | E8: 8.06 | F8: 5.96 | G8: 6.99 | H8: 5.93 | I8: 6.97
A9: 10 | B9: 4.05 | C9: 4.71 | D9: 4.02 | E9: 4.7 | F9: 3.5 | G9: 4.08 | H9: 3.48 | I9: 4.06
A10: 16 | B10: 2.6 | C10: 3 | D10: 2.57 | E10: 2.98 | F10: 2.25 | G10: 2.59 | H10: 2.23 | I10: 2.58
A11: 25 | B11: 1.72 | C11: 1.96 | D11: 1.7 | E11: 1.95 | F11: 1.49 | G11: 1.69 | H11: 1.47 | I11: 1.68
A12: 35 | B12: 1.26 | C12: 1.41 | D12: 1.24 | E12: 1.4 | F12: 1.09 | G12: 1.22 | H12: 1.07 | I12: 1.21
A13: 50 | B13: 0.91 | C13: 1 | D13: 0.89 | E13: 0.99 | F13: 0.79 | G13: 0.87 | H13: 0.77 | I13: 0.86
A14: 70 | B14: 0.68 | C14: 0.72 | D14: 0.66 | E14: 0.72 | F14: 0.59 | G14: 0.63 | H14: 0.57 | I14: 0.62
A15: 95 | B15: 0.54 | C15: 0.56 | D15: 0.52 | E15: 0.55 | F15: 0.47 | G15: 0.49 | H15: 0.45 | I15: 0.48
A16: 120 | B16: 0.45 | C16: 0.45 | D16: 0.43 | E16: 0.45 | F16: 0.39 | G16: 0.39 | H16: 0.38 | I16: 0.39
... A22: 500 | B22: 0.2 | C22: 0.16 | D22: 0.19 | E22: 0.16 | F22: 0.17 | G22: 0.14 | H22: 0.17 | I22: 0.14
A24: Tabela 22 - Queda de Tensão - Sintenax Flex (cobre)
A25: Seção nominal (mm²) | B25: 2x1 | D25: 1x2 | F25: 3x1 | H25: 1x3
B26: FP=0,8 | C26: FP=0,95 | D26: FP=0,8 | E26: FP=0,95 | F26: FP=0,8 | G26: FP=0,95 | H26: FP=0,8 | I26: FP=0,95
B27: (V/A.km) | C27: (V/A.km) | D27: (V/A.km) | E27: (V/A.km) | F27: (V/A.km) | G27: (V/A.km) | H27: (V/A.km) | I27: (V/A.km)
A28: 1.5 | B28: 25.63 | C28: 30.31 | D28: 25.59 | E28: 30.29 | F28: 22.17 | G28: 26.22 | H28: 22.14 | I28: 26.2
A29: 2.5 | B29: 15.46 | C29: 18.24 | D29: 15.42 | E29: 18.22 | F29: 13.37 | G29: 15.77 | H29: 13.34 | I29: 15.76
A30: 4 | B30: 9.65 | C30: 11.34 | D30: 9.61 | E30: 11.32 | F30: 8.35 | G30: 9.81 | H30: 8.32 | I30: 9.8
A31: 6 | B31: 6.48 | C31: 7.59 | D31: 6.45 | E31: 7.57 | F31: 5.6 | G31: 6.56 | H31: 5.58 | I31: 6.55
A32: 10 | B32: 3.81 | C32: 4.43 | D32: 3.79 | E32: 4.41 | F32: 3.29 | G32: 3.82 | H32: 3.27 | I32: 3.81
A33: 16 | B33: 2.45 | C33: 2.83 | D33: 2.43 | E33: 2.81 | F33: 2.12 | G33: 2.44 | H33: 2.1 | I33: 2.43
A34: 25 | B34: 1.63 | C34: 1.85 | D34: 1.61 | E34: 1.83 | F34: 1.41 | G34: 1.6 | H34: 1.39 | I34: 1.59
A35: 35 | B35: 1.19 | C35: 1.33 | D35: 1.17 | E35: 1.32 | F35: 1.03 | G35: 1.15 | H35: 1.01 | I35: 1.14
A36: 50 | B36: 0.87 | C36: 0.94 | D36: 0.85 | E36: 0.94 | F36: 0.75 | G36: 0.82 | H36: 0.74 | I36: 0.81
A37: 70 | B37: 0.64 | C37: 0.68 | D37: 0.63 | E37: 0.67 | F37: 0.56 | G37: 0.59 | H37: 0.54 | I37: 0.59
A38: 95 | B38: 0.52 | C38: 0.53 | D38: 0.5 | E38: 0.53 | F38: 0.45 | G38: 0.46 | H38: 0.43 | I38: 0.46
A39: 120 | B39: 0.43 | C39: 0.43 | D39: 0.41 | E39: 0.42 | F39: 0.37 | G39: 0.37 | H39: 0.36 | I39: 0.37
... A45: 500 | B45: 0.19 | C45: 0.16 | D45: 0.19 | E45: 0.15 | F45: 0.17 | G45: 0.14 | H45: 0.16 | I45: 0.14

Sheet Fatores de correção
A1: Tabela 11 - Fatores de correção para temperatura ambiente diferente de 30 °C para linhas não subterrâneas
A2: e de 20 °C (temperatura do solo) para linhas subterrâneas, conforme tabela 40 da NBR 5410:2004
A4: AMBIENTE | D4: SOLO
A5: Temp. | B5: PVC | C5: EPR | D5: PVC | E5: EPR
A6: 10 | B6: 1.22 | C6: 1.15 | D6: 1.1 | E6: 1.07
A7: 15 | B7: 1.17 | C7: 1.12 | D7: 1.05 | E7: 1.04
A8: 20 | B8: 1.12 | C8: 1.08 | D8: 0.95 | E8: 0.96
A9: 25 | B9: 1.06 | C9: 1.04 | D9: 0.89 | E9: 0.93
A10: 35 | B10: 0.94 | C10: 0.96 | D10: 0.84 | E10: 0.89
A11: 40 | B11: 0.87 | C11: 0.91 | D11: 0.77 | E11: 0.85
A12: 45 | B12: 0.79 | C12: 0.87 | D12: 0.71 | E12: 0.8
A13: 50 | B13: 0.71 | C13: 0.82 | D13: 0.63 | E13: 0.76
A14: 55 | B14: 0.61 | C14: 0.76 | D14: 0.55 | E14: 0.71
A15: 60 | B15: 0.5 | C15: 0.71 | D15: 0.45 | E15: 0.65
A16: 65 | B16: - | C16: 0.65 | D16: - | E16: 0.6
A17: 70 | B17: - | C17: 0.58 | D17: - | E17: 0.53
A18: 75 | B18: - | C18: 0.5 | D18: - | E18: 0.46
A19: 80 | B19: - | C19: 0.41 | D19: - | E19: 0.38
A21: Tabela 13 - Fatores de correção aplicáveis a condutores agrupados em feixe (em linhas abertas ou fechadas) e a condutores agrupados num mesmo plano, em camada única
A23: Método de instalação | B23: 1 | C23: 2 | D23: 3 | E23: 4 | F23: 5 | G23: 6 | H23: 7 | I23: 8 | J23: 9 | K23: 10 | L23: 11 | M23: 12
A24: Métodos A a F | B24: 1 | C24: 0.8 | D24: 0.7 | E24: 0.65 | F24: 0.6 | G24: 0.57 | H24: 0.54 | I24: 0.52 | J24: 0.5 | K24: 0.45 | L24: 0.41 | M24: 0.38
A25: Método C | B25: 1 | C25: 0.85 | D25: 0.79 | E25: 0.75 | F25: 0.73 | G25: 0.72 | H25: 0.72 | I25: 0.71 | J25: 0.7
A26: Método C | B26: 0.95 | C26: 0.81 | D26: 0.72 | E26: 0.68 | F26: 0.66 | G26: 0.64 | H26: 0.63 | I26: 0.62 | J26: 0.61
A27: Métodos E e F | B27: 1 | C27: 0.88 | D27: 0.82 | E27: 0.77 | F27: 0.75 | G27: 0.73 | H27: 0.73 | I27: 0.72 | J27: 0.72 | K27: 0.68 | L27: 0.62 | M27: 0.57
A30: Tabela 14 - Fatores de correção aplicáveis a agrupamentos consistindo em mais de uma camada de condutores - Métodos de Referência C, E e F
A32: Quantidade de camadas | B32: Quantidade de circuitos trifásicos ou de cabos multipolares por camada - 2 | C32: Quantidade de circuitos trifásicos ou de cabos multipolares por camada - 3 | D32: Quantidade de circuitos trifásicos ou de cabos multipolares por camada - 4 ou 5 | E32: Quantidade de circuitos trifásicos ou de cabos multipolares por camada - 6 a 8 | F32: Quantidade de circuitos trifásicos ou de cabos multipolares por camada - 9 e mais
A33: 2 | B33: 0.68 | C33: 0.62 | D33: 0.6 | E33: 0.58 | F33: 0.56
A34: 3 | B34: 0.62 | C34: 0.57 | D34: 0.55 | E34: 0.53 | F34: 0.51
A35: 4 ou 5 | B35: 0.6 | C35: 0.55 | D35: 0.52 | E35: 0.51 | F35: 0.49
A36: 6 a 8 | B36: 0.58 | C36: 0.53 | D36: 0.51 | E36: 0.49 | F36: 0.48
A37: 9 e mais | B37: 0.56 | C37: 0.51 | D37: 0.49 | E37: 0.48 | F37: 0.46
A39: Tabela 16 - Fatores de redução para mais do que um circuito formado por cabo multipolar em duto individual enterrado
A41: Número de circuitos | B41: Distância entre dutos(1) (a) - Nula | C41: Distância entre dutos(1) (a) - 0,25 m | D41: Distância entre dutos(1) (a) - 0,5 m | E41: Distância entre dutos(1) (a) - 1,0 m
A42: 2 | B42: 0.85 | C42: 0.9 | D42: 0.95 | E42: 0.95
A43: 3 | B43: 0.75 | C43: 0.85 | D43: 0.9 | E43: 0.95
A44: 4 | B44: 0.7 | C44: 0.8 | D44: 0.85 | E44: 0.9
A45: 5 | B45: 0.65 | C45: 0.8 | D45: 0.85 | E45: 0.9
A46: 6 | B46: 0.6 | C46: 0.8 | D46: 0.8 | E46: 0.8
A47: 7 | B47: 0.57 | C47: 0.76 | D47: 0.8 | E47: 0.88
A48: 8 | B48: 0.54 | C48: 0.74 | D48: 0.78 | E48: 0.88
...

Sheet CABLES1
A1: * Método de instalação: B2 / EPR/PVC | M1: * Método de instalação: D / EPR/PVC | X1: * Método de instalação: E / EPR/PVC | AI1: * Método de instalação: F / EPR/PVC | AT1: * Método de instalação: B1 / EPR/PVC | BF1: EPROTENAX, EPROTENAX GSETTE E AFUMEX | BL1: DISJUNTOR | BM1: T. DE CORRENTE | BO1: 440V | BS1: 380V | BW1: 220V
A2: SECCION (mm2) | B2: Imax (A) | C2: Imax (A) | D2: SECCION (mm2) | E2: Cabos Bi e Tripolares | H2: Cabos Unipolar Trifólio | M2: SECCION (mm2) | N2: Imax (A) | O2: Imax (A) | P2: SECCION (mm2) | Q2: Cabos Bi e Tripolares | T2: Cabos Unipolar Trifólio | X2: SECCION (mm2) | Y2: Imax (A) | Z2: Imax (A) | AA2: SECCION (mm2) | AB2: Tripolares | AE2: Cabos Unipolar Trifólio | AI2: SECCION (mm2) | AJ2: Imax (A) | AK2: Imax (A) | AL2: SECCION (mm2) | AM2: Tripolares | AP2: Cabos Unipolar Trifólio | AT2: SECCION (mm2) | AU2: Imax (A) | AV2: Imax (A) | AW2: SECCION (mm2) | AX2: Cabos Bi e Tripolares | BA2: Cabos Unipolar Trifólio | BF2: TRIPOLARES E TETRAPOLARES | BH2: UNIPOLAR - TRIFÓLIO | BO2: 460V
C3: Imax (A) | E3: RCA (ohm/km) | F3: XL | G3: Diâmetro | H3: RCA (ohm/km) | I3: XL | J3: Diâmetro | K3: RCC | O3: Imax (A) | Q3: RCA (ohm/km) | R3: XL | S3: Diâmetro | T3: RCA (ohm/km) | U3: XL | V3: Diâmetro | Z3: Imax (A) | AB3: RCA (ohm/km) | AC3: XL | AD3: Diâmetro | AE3: RCA (ohm/km) | AF3: XL | AG3: Diâmetro | AK3: Imax (A) | AM3: RCA (ohm/km) | AN3: XL | AO3: Diâmetro | AP3: RCA (ohm/km) | AQ3: XL | AR3: Diâmetro | AV3: Imax (A) | AX3: RCA (ohm/km) | AY3: XL | AZ3: Diâmetro | BA3: RCA (ohm/km) | BB3: XL | BC3: Diâmetro | BD3: RCC | BF3: FP=0,8 | BG3: FP=0,95 | BH3: FP=0,8 | BI3: FP=0,95 | BO3: (kW ) | BP3: Disj. Motor | BQ3: contator | BR3: relé | BS3: (kW ) | BT3: Disj. Motor | BU3: contator | BV3: relé | BW3: (kW ) | BX3: Disj. Motor | BY3: contator | BZ3: relé
B4: 2 Condutres Carregados | C4: 3 Condutores Carregados | F4: (ohm/km) | G4: Externo (tri) | I4: (ohm/km) | J4: Externo (trifolio) | N4: 2 Condutres Carregados | O4: 3 Condutres Carregados | R4: (ohm/km) | S4: Externo (tri) | U4: (ohm/km) | V4: Externo (trifolio) | Y4: 2 Condutres Carregados | Z4: 3 Condutores Carregados | AC4: (ohm/km) | AD4: Externo (tri) | AF4: (ohm/km) | AG4: Externo (trifolio) | AJ4: 2 Condutres Carregados | AK4: 3 Condutores Carregados | AN4: (ohm/km) | AO4: Externo (tri) | AQ4: (ohm/km) | AR4: Externo (trifolio) | AU4: 2 Condutres Carregados | AV4: 3 Condutores Carregados | AY4: (ohm/km) | AZ4: Externo (tri) | BB4: (ohm/km) | BC4: Externo (trifolio) | BF4: - | BG4: - | BH4: - | BI4: -
A5: 2.5 | B5: 30 | C5: 26 | D5: 2.5 | E5: 8.87 | F5: 0.12 | G5: 9.6 | H5: 8.87 | I5: 0.15 | J5: 5.4 | K5: 7.41 | M5: 2.5 | N5: 34 | O5: 29 | P5: 2.5 | Q5: 8.87 | R5: 0.12 | S5: 9.6 | T5: 8.87 | U5: 0.15 | V5: 5.4 | X5: 2.5 | Y5: 36 | Z5: 32 | AA5: 2.5 | AB5: 8.87 | AC5: 0.12 | AD5: 9.6 | AE5: 8.87 | AF5: 0.15 | AG5: 5.4 | AI5: 2.5 | AJ5: 37 | AK5: 29 | AL5: 2.5 | AM5: 8.87 | AN5: 0.12 | AO5: 9.6 | AP5: 8.87 | AQ5: 0.15 | AR5: 5.4 | AT5: 2.5 | AU5: 31 | AV5: 28 | AW5: 2.5 | AX5: 8.87 | AY5: 0.12 | AZ5: 9.6 | BA5: 8.87 | BB5: 0.15 | BC5: 5.4 | BD5: 7.41 | BF5: 0.2 | BG5: 0.18 | BH5: 0.21 | BI5: 0.18 | BJ5: 300 | BL5: 6 | BM5: 100 | BO5: 0.12 | BP5: 0,4-0,63A | BQ5: - | BR5: 0,45-0,63 | BS5: 0.16 | BT5: 0,4-0,63A | BV5: 0,55-0,8 | BW5: 0.16 | BX5: 0,63-1A | BY5: 9 | BZ5: 0,9-1,25
A6: 4 | B6: 35 | C6: 45 | D6: 4 | E6: 5.52 | F6: 0.12 | G6: 10.7 | H6: 5.52 | I6: 0.14 | J6: 5.9 | K6: 4.61 | M6: 4 | N6: 44 | O6: 37 | P6: 4 | Q6: 5.52 | R6: 0.12 | S6: 10.7 | T6: 5.52 | U6: 0.14 | V6: 5.9 | X6: 4 | Y6: 49 | Z6: 42 | AA6: 4 | AB6: 5.52 | AC6: 0.12 | AD6: 10.7 | AE6: 5.52 | AF6: 0.14 | AG6: 5.9 | AI6: 4 | AJ6: 50 | AK6: 40 | AL6: 4 | AM6: 5.52 | AN6: 0.12 | AO6: 10.7 | AP6: 5.52 | AQ6: 0.14 | AR6: 5.9 | AT6: 4 | AU6: 42 | AV6: 37 | AW6: 4 | AX6: 5.52 | AY6: 0.12 | AZ6: 10.7 | BA6: 5.52 | BB6: 0.14 | BC6: 5.9 | BD6: 4.61 | BF6: 0.22 | BG6: 0.21 | BH6: 0.23 | BI6: 0.21 | BJ6: 240 | BL6: 10 | BM6: 125 | BO6: 0.16 | BP6: 0,4-0,63A | BQ6: - | BR6: 0,45-0,63 | BS6: 0.16 | BT6: 0,4-0,63A | BV6: 0,55-0,8 | BW6: 0.16 | BX6: 0,63-1A | BY6: 9 | BZ6: 0,9-1,25
A7: 6 | B7: 44 | C7: 58 | D7: 6 | E7: 3.69 | F7: 0.11 | G7: 11.9 | H7: 3.69 | I7: 0.14 | J7: 6.5 | K7: 3.08 | M7: 6 | N7: 56 | O7: 46 | P7: 6 | Q7: 3.69 | R7: 0.11 | S7: 11.9 | T7: 3.69 | U7: 0.14 | V7: 6.5 | X7: 6 | Y7: 63 | Z7: 54 | AA7: 6 | AB7: 3.69 | AC7: 0.11 | AD7: 11.9 | AE7: 3.69 | AF7: 0.14 | AG7: 6.5 | AI7: 6 | AJ7: 65 | AK7: 53 | AL7: 6 | AM7: 3.69 | AN7: 0.11 | AO7: 11.9 | AP7: 3.69 | AQ7: 0.14 | AR7: 6.5 | AT7: 6 | AU7: 54 | AV7: 48 | AW7: 6 | AX7: 3.69 | AY7: 0.11 | AZ7: 11.9 | BA7: 3.69 | BB7: 0.14 | BC7: 6.5 | BD7: 3.08 | BF7: 0.26 | BG7: 0.25 | BH7: 0.27 | BI7: 0.26 | BJ7: 185 | BL7: 16 | BM7: 150 | BO7: 0.25 | BP7: 4 | BQ7: - | BR7: 0,55-0,8 | BS7: 0.25 | BT7: 4 | BV7: 0,7-1 | BW7: 0.25 | BX7: 6 | BY7: 9 | BZ7: 1,1-1,6
A8: 10 | B8: 59 | C8: 60 | D8: 10 | E8: 2.19 | F8: 0.1 | G8: 14.3 | H8: 2.19 | I8: 0.13 | J8: 7.7 | K8: 1.83 | M8: 10 | N8: 73 | O8: 61 | P8: 10 | Q8: 2.19 | R8: 0.1 | S8: 14.3 | T8: 2.19 | U8: 0.13 | V8: 7.7 | X8: 10 | Y8: 86 | Z8: 75 | AA8: 10 | AB8: 2.19 | AC8: 0.1 | AD8: 14.3 | AE8: 2.19 | AF8: 0.13 | AG8: 7.7 | AI8: 10 | AJ8: 90 | AK8: 74 | AL8: 10 | AM8: 2.19 | AN8: 0.1 | AO8: 14.3 | AP8: 2.19 | AQ8: 0.13 | AR8: 7.7 | AT8: 10 | AU8: 75 | AV8: 66 | AW8: 10 | AX8: 2.19 | AY8: 0.1 | AZ8: 14.3 | BA8: 2.19 | BB8: 0.13 | BC8: 7.7 | BD8: 1.83 | BF8: 0.3 | BG8: 0.3 | BH8: 0.32 | BI8: 0.31 | BJ8: 150 | BL8: 20 | BM8: 200 | BO8: 0.33 | BP8: 4 | BQ8: - | BR8: 0,9-1,25 | BS8: 0.33 | BT8: 4 | BV8: 0,9-1,25 | BW8: 0.33 | BX8: 10 | BY8: 9 | BZ8: 1,8-2,5
A9: 16 | B9: 91 | C9: 80 | D9: 16 | E9: 1.38 | F9: 0.1 | G9: 19.1 | H9: 1.38 | I9: 0.12 | J9: 9.3 | K9: 1.15 | M9: 16 | N9: 95 | O9: 79 | P9: 16 | Q9: 1.38 | R9: 0.1 | S9: 19.1 | T9: 1.38 | U9: 0.12 | V9: 9.3 | X9: 16 | Y9: 115 | Z9: 100 | AA9: 16 | AB9: 1.38 | AC9: 0.1 | AD9: 19.1 | AE9: 1.38 | AF9: 0.12 | AG9: 9.3 | AI9: 16 | AJ9: 121 | AK9: 101 | AL9: 16 | AM9: 1.38 | AN9: 0.1 | AO9: 19.1 | AP9: 1.38 | AQ9: 0.12 | AR9: 9.3 | AT9: 16 | AU9: 100 | AV9: 88 | AW9: 16 | AX9: 1.38 | AY9: 0.1 | AZ9: 19.1 | BA9: 1.38 | BB9: 0.12 | BC9: 9.3 | BD9: 1.15 | BF9: 0.35 | BG9: 0.35 | BH9: 0.36 | BI9: 0.36 | BJ9: 120 | BL9: 25 | BM9: 250 | BO9: 0.5 | BP9: 6 | BQ9: - | BR9: 1,1-1,6 | BS9: 0.5 | BT9: 6 | BU9: 9 | BV9: 1,1-1,6 | BW9: 0.5 | BX9: 10 | BY9: 9 | BZ9: 2,2-3,2
A10: 25 | B10: 119 | C10: 105 | D10: 25 | E10: 0.87 | F10: 0.1 | G10: 23.3 | H10: 0.87 | I10: 0.11 | J10: 11.4 | K10: 0.73 | M10: 25 | N10: 121 | O10: 101 | P10: 25 | Q10: 0.87 | R10: 0.1 | S10: 23.3 | T10: 0.87 | U10: 0.11 | V10: 11.4 | X10: 25 | Y10: 149 | Z10: 127 | AA10: 25 | AB10: 0.87 | AC10: 0.1 | AD10: 23.3 | AE10: 0.87 | AF10: 0.11 | AG10: 11.4 | AI10: 25 | AJ10: 161 | AK10: 135 | AL10: 25 | AM10: 0.87 | AN10: 0.1 | AO10: 23.3 | AP10: 0.87 | AQ10: 0.11 | AR10: 11.4 | AT10: 25 | AU10: 133 | AV10: 117 | AW10: 25 | AX10: 0.87 | AY10: 0.1 | AZ10: 23.3 | BA10: 0.87 | BB10: 0.11 | BC10: 11.4 | BD10: 0.73 | BF10: 0.42 | BG10: 0.44 | BH10: 0.43 | BI10: 0.44 | BJ10: 95 | BL10: 32 | BM10: 300 | BO10: 0.75 | BP10: 6 | BQ10: 9 | BR10: 1,4-2 | BS10: 0.75 | BT10: 6 | BU10: 9 | BV10: 1,4-2 | BW10: 0.75 | BX10: 16 | BY10: 9 | BZ10: 2,8-4
A11: 35 | B11: 146 | C11: 128 | D11: 35 | E11: 0.63 | F11: 0.09 | G11: 26.3 | H11: 0.63 | I11: 0.11 | J11: 12.7 | K11: 0.52 | M11: 35 | N11: 146 | O11: 122 | P11: 35 | Q11: 0.63 | R11: 0.09 | S11: 26.3 | T11: 0.63 | U11: 0.11 | V11: 12.7 | X11: 35 | Y11: 185 | Z11: 158 | AA11: 35 | AB11: 0.63 | AC11: 0.09 | AD11: 26.3 | AE11: 0.63 | AF11: 0.11 | AG11: 12.7 | AI11: 35 | AJ11: 200 | AK11: 169 | AL11: 35 | AM11: 0.63 | AN11: 0.09 | AO11: 26.3 | AP11: 0.63 | AQ11: 0.11 | AR11: 12.7 | AT11: 35 | AU11: 164 | AV11: 144 | AW11: 35 | AX11: 0.63 | AY11: 0.09 | AZ11: 26.3 | BA11: 0.63 | BB11: 0.11 | BC11: 12.7 | BD11: 0.52 | BF11: 0.54 | BG11: 0.58 | BH11: 0.56 | BI11: 0.59 | BJ11: 70 | BL11: 40 | BM11: 400 | BO11: 1 | BP11: 10 | BQ11: 9 | BR11: 1,8-2,5 | BS11: 1 | BT11: 10 | BU11: 9 | BV11: 2,2-3,2 | BW11: 1 | BX11: 20 | BY11: 9 | BZ11: 3,5-5
A12: 50 | B12: 175 | C12: 154 | D12: 50 | E12: 0.46 | F12: 0.09 | G12: 30.4 | H12: 0.46 | I12: 0.11 | J12: 14.7 | K12: 0.39 | M12: 50 | N12: 173 | O12: 144 | P12: 50 | Q12: 0.46 | R12: 0.09 | S12: 30.4 | T12: 0.46 | U12: 0.11 | V12: 14.7 | X12: 50 | Y12: 225 | Z12: 192 | AA12: 50 | AB12: 0.46 | AC12: 0.09 | AD12: 30.4 | AE12: 0.46 | AF12: 0.11 | AG12: 14.7 | AI12: 50 | AJ12: 242 | AK12: 207 | AL12: 50 | AM12: 0.46 | AN12: 0.09 | AO12: 30.4 | AP12: 0.46 | AQ12: 0.11 | AR12: 14.7 | AT12: 50 | AU12: 198 | AV12: 175 | AW12: 50 | AX12: 0.46 | AY12: 0.09 | AZ12: 30.4 | BA12: 0.46 | BB12: 0.11 | BC12: 14.7 | BD12: 0.39 | BF12: 0.75 | BG12: 0.82 | BH12: 0.76 | BI12: 0.83 | BJ12: 50 | BL12: 50 | BM12: 500 | BO12: 1.5 | BP12: 10 | BQ12: 9 | BR12: 2,2-3,2 | BS12: 1.5 | BT12: 16 | BU12: 9 | BV12: 2,8-4 | BW12: 1.5 | BX12: 20 | BY12: 9 | BZ12: 5,5-8
A13: 70 | B13: 221 | C13: 194 | D13: 70 | E13: 0.32 | F13: 0.09 | G13: 35 | H13: 0.32 | I13: 0.1 | J13: 16.8 | K13: 0.27 | M13: 70 | N13: 213 | O13: 178 | P13: 70 | Q13: 0.32 | R13: 0.09 | S13: 35 | T13: 0.32 | U13: 0.1 | V13: 16.8 | X13: 70 | Y13: 289 | Z13: 246 | AA13: 70 | AB13: 0.32 | AC13: 0.09 | AD13: 35 | AE13: 0.32 | AF13: 0.1 | AG13: 16.8 | AI13: 70 | AJ13: 310 | AK13: 268 | AL13: 70 | AM13: 0.32 | AN13: 0.09 | AO13: 35 | AP13: 0.32 | AQ13: 0.1 | AR13: 16.8 | AT13: 70 | AU13: 253 | AV13: 222 | AW13: 70 | AX13: 0.32 | AY13: 0.09 | AZ13: 35 | BA13: 0.32 | BB13: 0.1 | BC13: 16.8 | BD13: 0.27 | BF13: 0.98 | BG13: 1.09 | BH13: 0.99 | BI13: 1.1 | BJ13: 35 | BL13: 63 | BM13: 600 | BO13: 2 | BP13: 20 | BQ13: 9 | BR13: 3,5-5 | BS13: 2 | BT13: 20 | BU13: 9 | BV13: 3,5-5 | BW13: 2 | BX13: 20 | BY13: 9 | BZ13: 7-10
A14: 95 | B14: 255 | C14: 233 | D14: 95 | E14: 0.23 | F14: 0.09 | G14: 40 | H14: 0.23 | I14: 0.1 | J14: 19.2 | K14: 0.19 | M14: 95 | N14: 252 | O14: 211 | P14: 95 | Q14: 0.23 | R14: 0.09 | S14: 40 | T14: 0.23 | U14: 0.1 | V14: 19.2 | X14: 95 | Y14: 352 | Z14: 298 | AA14: 95 | AB14: 0.23 | AC14: 0.09 | AD14: 40 | AE14: 0.23 | AF14: 0.1 | AG14: 19.2 | AI14: 95 | AJ14: 377 | AK14: 328 | AL14: 95 | AM14: 0.23 | AN14: 0.09 | AO14: 40 | AP14: 0.23 | AQ14: 0.1 | AR14: 19.2 | AT14: 95 | AU14: 306 | AV14: 269 | AW14: 95 | AX14: 0.23 | AY14: 0.09 | AZ14: 40 | BA14: 0.23 | BB14: 0.1 | BC14: 19.2 | BD14: 0.19 | BF14: 1.32 | BG14: 1.5 | BH14: 1.34 | BI14: 1.51 | BJ14: 25 | BL14: 80 | BM14: 800 | BO14: 3 | BP14: 20 | BQ14: 9 | BR14: 4,5-6,3 | BS14: 3 | BT14: 20 | BU14: 9 | BV14: 5,5-8 | BW14: 3 | BX14: 20 | BY14: 12 | BZ14: 9-12
A15: 120 | B15: 305 | C15: 268 | D15: 120 | E15: 0.19 | F15: 0.09 | G15: 44.8 | H15: 0.19 | I15: 0.1 | J15: 21.3 | K15: 0.15 | M15: 120 | N15: 287 | O15: 240 | P15: 120 | Q15: 0.19 | R15: 0.09 | S15: 44.8 | T15: 0.19 | U15: 0.1 | V15: 21.3 | X15: 120 | Y15: 410 | Z15: 346 | AA15: 120 | AB15: 0.19 | AC15: 0.09 | AD15: 44.8 | AE15: 0.19 | AF15: 0.1 | AG15: 21.3 | AI15: 120 | AJ15: 437 | AK15: 383 | AL15: 120 | AM15: 0.19 | AN15: 0.09 | AO15: 44.8 | AP15: 0.19 | AQ15: 0.1 | AR15: 21.3 | AT15: 120 | AU15: 354 | AV15: 312 | AW15: 120 | AX15: 0.19 | AY15: 0.09 | AZ15: 44.8 | BA15: 0.19 | BB15: 0.1 | BC15: 21.3 | BD15: 0.15 | BF15: 2.03 | BG15: 2.34 | BH15: 2.05 | BI15: 2.35 | BJ15: 16 | BL15: 100 | BM15: 1000 | BO15: 4 | BP15: 20 | BQ15: 9 | BR15: 5,5-8 | BS15: 4 | BT15: 20 | BU15: 9 | BV15: 7-10 | BW15: 4 | BX15: 25 | BY15: 18 | BZ15: 11-16
A16: 150 | B16: 349 | C16: 307 | D16: 150 | E16: 0.15 | F16: 0.09 | G16: 50.8 | H16: 0.15 | I16: 0.1 | J16: 23.7 | K16: 0.12 | M16: 150 | N16: 324 | O16: 271 | P16: 150 | Q16: 0.15 | R16: 0.09 | S16: 50.8 | T16: 0.15 | U16: 0.1 | V16: 23.7 | X16: 150 | Y16: 473 | Z16: 399 | AA16: 150 | AB16: 0.15 | AC16: 0.09 | AD16: 50.8 | AE16: 0.15 | AF16: 0.1 | AG16: 23.7 | AI16: 150 | AJ16: 504 | AK16: 444 | AL16: 150 | AM16: 0.15 | AN16: 0.09 | AO16: 50.8 | AP16: 0.15 | AQ16: 0.1 | AR16: 23.7 | AT16: 150 | AU16: 407 | AV16: 358 | AW16: 150 | AX16: 0.15 | AY16: 0.09 | AZ16: 50.8 | BA16: 0.15 | BB16: 0.1 | BC16: 23.7 | BD16: 0.12 | BF16: 3.2 | BG16: 3.7 | BH16: 3.2 | BI16: 3.7 | BJ16: 10 | BL16: 125 | BM16: 1200 | BO16: 5 | BP16: 20 | BQ16: 9 | BR16: 7-10 | BS16: 5 | BT16: 20 | BU16: 9 | BV16: 9-12 | BW16: 5 | BX16: 25 | BY16: 18 | BZ16: 11-16
A17: 185 | B17: 395 | C17: 348 | D17: 185 | E17: 0.12 | F17: 0.09 | G17: 55.7 | H17: 0.12 | I17: 0.1 | J17: 25.8 | K17: 0.099 | M17: 185 | N17: 363 | O17: 304 | P17: 185 | Q17: 0.12 | R17: 0.09 | S17: 55.7 | T17: 0.12 | U17: 0.1 | V17: 25.8 | X17: 185 | Y17: 542 | Z17: 456 | AA17: 185 | AB17: 0.12 | AC17: 0.09 | AD17: 55.7 | AE17: 0.12 | AF17: 0.1 | AG17: 25.8 | AI17: 185 | AJ17: 575 | AK17: 510 | AL17: 185 | AM17: 0.12 | AN17: 0.09 | AO17: 55.7 | AP17: 0.12 | AQ17: 0.1 | AR17: 25.8 | AT17: 185 | AU17: 464 | AV17: 408 | AW17: 185 | AX17: 0.12 | AY17: 0.09 | AZ17: 55.7 | BA17: 0.12 | BB17: 0.1 | BC17: 25.8 | BD17: 0.099 | BF17: 5.3 | BG17: 6.2 | BH17: 5.3 | BI17: 6.2 | BJ17: 6 | BL17: 150 | BM17: 1500 | BO17: 6 | BP17: 20 | BQ17: 12 | BR17: 9-12 | BS17: 6 | BT17: 20 | BU17: 12 | BV17: 9-12 | BW17: 6 | BX17: 32 | BY17: 25 | BZ17: 17-22
A18: 240 | B18: 452 | C18: 407 | D18: 240 | E18: 0.1 | F18: 0.09 | G18: 62.7 | H18: 0.09 | I18: 0.1 | J18: 29.2 | K18: 0.075 | M18: 240 | N18: 419 | O18: 351 | P18: 240 | Q18: 0.1 | R18: 0.09 | S18: 62.7 | T18: 0.09 | U18: 0.1 | V18: 29.2 | X18: 240 | Y18: 641 | Z18: 538 | AA18: 240 | AB18: 0.1 | AC18: 0.09 | AD18: 62.7 | AE18: 0.09 | AF18: 0.1 | AG18: 29.2 | AI18: 240 | AJ18: 679 | AK18: 607 | AL18: 240 | AM18: 0.1 | AN18: 0.09 | AO18: 62.7 | AP18: 0.09 | AQ18: 0.1 | AR18: 29.2 | AT18: 240 | AU18: 546 | AV18: 481 | AW18: 240 | AX18: 0.1 | AY18: 0.09 | AZ18: 62.7 | BA18: 0.09 | BB18: 0.1 | BC18: 29.2 | BD18: 0.075 | BF18: 7.9 | BG18: 9.3 | BH18: 7.9 | BI18: 9.3 | BJ18: 4 | BL18: 185 | BM18: 2000 | BO18: 7.5 | BP18: 25 | BQ18: 16 | BR18: 11-16 | BS18: 7.5 | BT18: 25 | BU18: 16 | BV18: 11-16 | BW18: 7.5 | BX18: 63 | BY18: 32 | BZ18: 22-32
A19: 300 | B19: 529 | C19: 465 | D19: 300 | E19: 0.078 | F19: 0.09 | G19: - | H19: 0.078 | I19: 0.1 | J19: - | K19: 0.06 | M19: 300 | N19: 474 | O19: 396 | P19: 300 | Q19: 0.078 | R19: 0.09 | S19: - | T19: 0.078 | U19: 0.1 | V19: - | X19: 300 | Y19: 741 | Z19: 621 | AA19: 300 | AB19: 0.078 | AC19: 0.09 | AD19: - | AE19: 0.078 | AF19: 0.1 | AG19: - | AI19: 300 | AJ19: 783 | AK19: 703 | AL19: 300 | AM19: 0.078 | AN19: 0.09 | AO19: - | AP19: 0.078 | AQ19: 0.1 | AR19: - | AT19: 300 | AU19: 628 | AV19: 553 | AW19: 300 | AX19: 0.078 | AY19: 0.09 | AZ19: - | BA19: 0.078 | BB19: 0.1 | BC19: - | BD19: 0.06 | BF19: 12.7 | BG19: 15 | BH19: 12.7 | BI19: 15 | BJ19: 2.5 | BL19: 200 | BM19: 2500 | BO19: 10 | BP19: 25 | BQ19: 16 | BR19: 11-16 | BS19: 10 | BT19: 32 | BU19: 16 | BV19: 11-16 | BW19: 10 | BX19: 63 | BY19: 32 | BZ19: 22-32
BL20: 250 | BM20: 2500 | BO20: 10 | BP20: 25 | BQ20: 18 | BR20: 11-16 | BS20: 10 | BT20: 32 | BU20: 18 | BV20: 14-20 | BW20: 10 | BX20: 63 | BY20: 32 | BZ20: 22-32
BL21: 320 | BM21: 3000 | BO21: 12.5 | BP21: 32 | BQ21: 25 | BR21: 14-20 | BS21: 12.5 | BT21: 32 | BU21: 18 | BV21: 15-25 | BW21: 12.5 | BX21: 63 | BY21: 40 | BZ21: 28-40
A22: 1x2 | B22: 1x3 | C22: 1x3 BL | D22: 1x4 | E22: 2x1 | F22: 3x1 | G22: 4x1 | M22: CARACT. ELETR. | BL22: 400 | BO22: 15 | BP22: 32 | BQ22: 25 | BR22: 14-20 | BS22: 15 | BT22: 32 | BU22: 18 | BV22: 15-25 | BW22: 15 | BX22: 63 | BY22: 40 | BZ22: 28-40
A23: B2 | B23: D | C23: E | D23: F | E23: B1 | M23: IN | N23: mm | O23: ø ELETR. | BL23: 500 | BO23: 15 | BP23: 63 | BQ23: 32 | BR23: 22-32 | BS23: 15 | BT23: 63 | BU23: 32 | BV23: 22-32 | BW23: 15 | BX23: 80 | BY23: 50 | BZ23: 40-50
A24: 110 | B24: 120 | C24: 127 | D24: 220 | E24: 380 | F24: 440 | G24: 480 | H24: 13800 | M24: 3/8" | N24: 12.44 | O24: =IF($CD$13=1,$CM$10,IF($CD$11=2,$CK$10,$CI$10)) -> 0 | BL24: 630 | BO24: 20 | BP24: 63 | BQ24: 32 | BR24: 22-32 | BS24: 20 | BT24: 63 | BU24: 32 | BV24: 22-32 | BW24: 20 | BX24: 80 | BY24: 50 | BZ24: 40-50
A25: HEPR | B25: PVC | M25: 1/2" | N25: 15.75 | O25: =IF($CD$13=1,$CM$10,IF($CD$11=2,$CK$10,$CI$10)) -> 0 | BL25: 800 | BO25: 20 | BP25: 63 | BQ25: 32 | BR25: 22-32 | BS25: 20 | BT25: 63 | BU25: 40 | BV25: 28-40 | BW25: 20 | BX25: 125 | BY25: 65 | BZ25: 45-63
M26: 3/4" | N26: 20.82 | O26: =IF($CD$13=1,$CM$10,IF($CD$11=2,$CK$10,$CI$10)) -> 0 | BL26: 1000 | BO26: 25 | BP26: 63 | BQ26: 40 | BR26: 28-40 | BS26: 25 | BT26: 80 | BU26: 50 | BV26: 40-50 | BW26: 25 | BX26: 160 | BY26: 80 | BZ26: 57-75
M27: 1" | N27: 26.41 | O27: =IF($CD$13=1,$CM$10,IF($CD$11=2,$CK$10,$CI$10)) -> 0 | BL27: 1250 | BO27: 30 | BP27: 80 | BQ27: 50 | BR27: 40-50 | BS27: 30 | BT27: 125 | BU27: 65 | BV27: 45-63 | BW27: 30 | BX27: 200 | BY27: 112 | BZ27: 50-200
M28: 1.1/2" | N28: 40.89 | O28: =IF($CD$13=1,$CM$10,IF($CD$11=2,$CK$10,$CI$10)) -> 0 | BL28: 1500 | BO28: 40 | BP28: 125 | BQ28: 65 | BR28: 45-63 | BS28: 40 | BT28: 160 | BU28: 80 | BV28: 57-75 | BW28: 40 | BX28: 200 | BY28: 112 | BZ28: 50-200
M29: 2" | N29: 52.32 | O29: =IF($CD$13=1,$CM$10,IF($CD$11=2,$CK$10,$CI$10)) -> 0 | BL29: 2000 | BO29: 50 | BP29: 160 | BQ29: 80 | BR29: 57-75 | BS29: 50 | BT29: 160 | BU29: 95 | BV29: 70-90 | BW29: 50 | BX29: 250 | BY29: 180 | BZ29: 50-200
M30: 2.1/2" | N30: 62.48 | O30: =IF($CD$13=1,$CM$10,IF($CD$11=2,$CK$10,$CI$10)) -> 0 | BL30: 2500 | BO30: 60 | BP30: 160 | BQ30: 95 | BR30: 70-90 | BS30: 60 | BT30: 200 | BU30: 105 | BV30: 50-200 | BW30: 60 | BX30: 315 | BY30: 180 | BZ30: 55-250
M31: 3" | N31: 77.72 | O31: =IF($CD$13=1,$CM$10,IF($CD$11=2,$CK$10,$CI$10)) -> 0 | BO31: 75 | BP31: 250 | BQ31: 150 | BR31: 50-200 | BS31: 75 | BT31: 250 | BU31: 150 | BV31: 50-200 | BW31: 75 | BX31: 400 | BY31: 250 | BZ31: 200-540
M32: 3.1/2" | N32: 89.91 | O32: =IF($CD$13=1,$CM$10,IF($CD$11=2,$CK$10,$CI$10)) -> 0 | BO32: 100 | BP32: 250 | BQ32: 180 | BR32: 50-200 | BS32: 100 | BT32: 315 | BU32: 180 | BV32: 50-200 | BW32: 100 | BX32: 400 | BY32: 300 | BZ32: 200-540
M33: 4" | N33: 102.1 | O33: =IF($CD$13=1,$CM$10,IF($CD$11=2,$CK$10,$CI$10)) -> 0 | BO33: 125 | BP33: 315 | BQ33: 180 | BR33: 50-200 | BS33: 125 | BT33: 400 | BU33: 250 | BV33: 55-250 | BW33: 125 | BX33: 400 | BY33: 400 | BZ33: 200-540
M34: 4.1/2" | N34: 114.3 | O34: =IF($CD$13=1,$CM$10,IF($CD$11=2,$CK$10,$CI$10)) -> 0 | BO34: 150 | BP34: 400 | BQ34: 250 | BR34: 55-250 | BS34: 150 | BT34: 400 | BU34: 250 | BV34: 200-540 | BW34: 150 | BX34: 630 | BY34: 490 | BZ34: 200-540
M35: 5" | N35: 128.01 | O35: =IF($CD$13=1,$CM$10,IF($CD$11=2,$CK$10,$CI$10)) -> 0 | BO35: 175 | BP35: 400 | BQ35: 250 | BR35: 200-540 | BS35: 175 | BT35: 400 | BU35: 300 | BV35: 200-540 | BW35: 175 | BX35: 630 | BY35: 490 | BZ35: 200-540
M36: 6" | N36: 153.92 | O36: =IF($CD$13=1,$CM$10,IF($CD$11=2,$CK$10,$CI$10)) -> 0 | BO36: 200 | BP36: 400 | BQ36: 300 | BR36: 200-540 | BS36: 200 | BT36: 400 | BU36: 400 | BV36: 200-540 | BW36: 200 | BX36: 800 | BY36: - | BZ36: -
BO37: 250 | BP37: 630 | BQ37: 400 | BR37: 200-540 | BS37: 250 | BT37: 630 | BU37: 400 | BV37: 200-540 | BW37: 250 | BX37: 630 | BY37: - | BZ37: -
M38: 3 COND. (40%) | BO38: 300 | BP38: 630 | BQ38: 400 | BR38: 200-540 | BS38: 300 | BT38: 630 | BU38: 490 | BV38: - | BW38: 300 | BX38: 630 | BY38: - | BZ38: -
M39: 2 COND.(31%) | BO39: 350 | BP39: 630 | BQ39: 490 | BR39: 200-540 | BS39: 350 | BT39: 800 | BU39: 490 | BV39: - | BW39: 350 | BX39: - | BY39: - | BZ39: -
M40: 1 COND. (53%) | BO40: 400 | BP40: 800 | BQ40: - | BR40: - | BS40: 400 | BT40: 800 | BV40: - | BW40: 400 | BX40: - | BY40: - | BZ40: -
...

Sheet MOTOR
A1: Potência | F1: rend | G1: f.p | I1: 440V | M1: 380V | Q1: 220V
E2: Corrente nominal em 220 V (A) | H2: Peso aprox. (kg)
A3: kW | B3: cv | C3: Carcaça | D3: rpm | I3: (kW ) | J3: Disj. Motor | K3: contator | L3: relé | M3: (kW ) | N3: Disj. Motor | O3: contator | P3: relé | Q3: (kW ) | R3: Disj. Motor | S3: contator | T3: relé
A4: 4 Pólos - 60 Hz
A5: 0.12 | B5: 0.16 | C5: 63 | D5: 1720 | F5: 0.61 | G5: 0.6 | H5: 7 | I5: 0.12 | J5: 0,63 | K5: 7 | L5: 0,45-0,63 | M5: 0.12 | N5: 0.63 | O5: 7 | P5: 0,45-0,63 | Q5: 0.12 | R5: 1 | S5: 7 | T5: 0,8-1,2
A6: 0.18 | B6: 0.25 | C6: 63 | D6: 1710 | F6: 0.665 | G6: 0.63 | H6: 7.5 | I6: 0.18 | J6: 0.63 | K6: 7 | L6: 0,63-0,8 | M6: 0.18 | N6: 1 | O6: 7 | P6: 0,63-0,8 | Q6: 0.18 | R6: 1.6 | S6: 7 | T6: 1,2-1,8
A7: 0.25 | B7: 0.33 | C7: 63 | D7: 1710 | F7: 0.685 | G7: 0.65 | H7: 8 | I7: 0.25 | J7: 1 | K7: 7 | L7: 0,63-0,8 | M7: 0.25 | N7: 1 | O7: 7 | P7: 0,8-1,2 | Q7: 0.25 | R7: 1.6 | S7: 7 | T7: 1,2-1,8
A8: 0.37 | B8: 0.5 | C8: 71 | D8: 1720 | F8: 0.72 | G8: 0.65 | H8: 10 | I8: 0.37 | J8: 1.6 | K8: 7 | L8: 0,8-1,2 | M8: 0.37 | N8: 1.6 | O8: 7 | P8: 1,2-1,8 | Q8: 0.37 | R8: 2.5 | S8: 7 | T8: 1,8-2,8
A9: 0.55 | B9: 0.75 | C9: 71 | D9: 1680 | F9: 0.75 | G9: 0.68 | H9: 11.5 | I9: 0.55 | J9: 1.6 | K9: 7 | L9: 1,2-1,8 | M9: 0.55 | N9: 2.5 | O9: 7 | P9: 1,8-2,8 | Q9: 0.55 | R9: 4 | S9: 7 | T9: 2,8-4
A10: 0.75 | B10: 1 | C10: 80 | D10: 1730 | F10: 0.826 | G10: 0.8 | H10: 18 | I10: 0.75 | J10: 1.6 | K10: 7 | L10: 1,2-1,8 | M10: 0.75 | N10: 2.5 | O10: 7 | P10: 1,8-2,8 | Q10: 0.75 | R10: 4 | S10: 7 | T10: 2,8-4
A11: 1.1 | B11: 1.5 | C11: 80 | D11: 1715 | F11: 0.815 | G11: 0.82 | H11: 16 | I11: 1.1 | J11: 2.5 | K11: 7 | L11: 1,8-2,8 | M11: 1.1 | N11: 4 | O11: 7 | P11: 1,8-2,8 | Q11: 1.1 | R11: 6.3 | S11: 7 | T11: 4-6,3
A12: 1.5 | B12: 2 | C12: 90S | D12: 1755 | F12: 0.842 | G12: 0.76 | H12: 20 | I12: 1.5 | J12: 4 | K12: 7 | L12: 4-6,3 | M12: 1.5 | N12: 4 | O12: 7 | P12: 2,8-4 | Q12: 1.5 | R12: 6.3 | S12: 7 | T12: 5,6-8
A13: 2.2 | B13: 3 | C13: 90L | D13: 1735 | F13: 0.851 | G13: 0.82 | H13: 23 | I13: 2.2 | J13: 6.3 | K13: 7 | L13: 4-6,3 | M13: 2.2 | N13: 6.3 | O13: 7 | P13: 4-6,3 | Q13: 2.2 | R13: 10 | S13: 9 | T13: 7-10
A14: 3 | B14: 4 | C14: 100L | D14: 1720 | F14: 0.865 | G14: 0.82 | H14: 30 | I14: 3 | J14: 6.3 | K14: 7 | L14: 4-6,3 | M14: 3 | N14: 10 | O14: 7 | P14: 5,6-8 | Q14: 3 | R14: 16 | S14: 12 | T14: 8-12,5
A15: 3.7 | B15: 5 | C15: 100L | D15: 1720 | F15: 0.88 | G15: 0.8 | H15: 33 | I15: 3.7 | J15: 10 | K15: 9 | L15: 5,6-8 | M15: 3.7 | N15: 10 | O15: 9 | P15: 7-10 | Q15: 3.7 | R15: 16 | S15: 16 | T15: 10-15
A16: 4.5 | B16: 6 | C16: 112M | D16: 1735 | F16: 0.89 | G16: 0.81 | H16: 45 | I16: 4.5 | J16: 10 | K16: 9 | L16: 7-10 | M16: 4.5 | N16: 10 | O16: 12 | P16: 8-12,5 | Q16: 4.5 | R16: 20 | S16: 18 | T16: 11-17
A17: 5.5 | B17: 7.5 | C17: 112M | D17: 1740 | F17: 0.9 | G17: 0.8 | H17: 46 | I17: 5.5 | J17: 10 | K17: 12 | L17: 9-12 | M17: 5.5 | N17: 16 | O17: 12 | P17: 10-15 | Q17: 5.5 | R17: 20 | S17: 25 | T17: 15-23
A18: 7.5 | B18: 10 | C18: 132S | D18: 1760 | F18: 0.91 | G18: 0.82 | H18: 65 | I18: 7.5 | J18: 16 | K18: 16 | L18: 10-15 | M18: 7.5 | N18: 16 | O18: 16 | P18: 11-17 | Q18: 7.5 | R18: 32 | S18: 32 | T18: 22-32
A19: 9.2 | B19: 12.5 | C19: 132M | D19: 1760 | F19: 0.91 | G19: 0.83 | H19: 75 | I19: 9.2 | J19: 16 | K19: 18 | L19: 11-17 | M19: 9.2 | N19: 20 | O19: 25 | P19: 15-23 | Q19: 9.2 | R19: 32 | S19: 32 | T19: 32-40
A20: 11 | B20: 15 | C20: 132M/L | D20: 1755 | F20: 0.917 | G20: 0.84 | H20: 78 | I20: 11 | J20: 20 | K20: 25 | L20: 15-23 | M20: 11 | N20: 25 | O20: 25 | P20: 15-23 | Q20: 11 | R20: 40 | S20: 40 | T20: 32-50
A21: 15 | B21: 20 | C21: 160M | D21: 1765 | F21: 0.924 | G21: 0.8 | H21: 120 | I21: 15 | J21: 32 | K21: 32 | L21: 22-32 | M21: 15 | N21: 32 | O21: 32 | P21: 32-40 | Q21: 15 | R21: 65 | S21: 65 | T21: 40-57
A22: 18.5 | B22: 25 | C22: 160L | D22: 1760 | F22: 0.926 | G22: 0.81 | H22: 135 | I22: 18.5 | J22: 32 | K22: 40 | L22: 32-40 | M22: 18.5 | N22: 40 | O22: 40 | P22: 32-40 | Q22: 18.5 | R22: 65 | S22: 65 | T22: 57-70
A23: 22 | B23: 30 | C23: 180M | D23: 1760 | F23: 0.93 | G23: 0.85 | H23: 185 | I23: 22 | J23: 40 | K23: 40 | L23: 32-40 | M23: 22 | N23: 50 | O23: 50 | P23: 32-50 | Q23: 22 | R23: 90 | S23: 80 | T23: 63-80
A24: 30 | B24: 40 | C24: 200M | D24: 1770 | F24: 0.93 | G24: 0.85 | H24: 218 | I24: 30 | J24: 50 | K24: 50 | L24: 40-57 | M24: 30 | N24: 65 | O24: 65 | P24: 50-63 | Q24: 30 | R24: 105 | S24: 105 | T24: 90-112
A25: 37 | B25: 50 | C25: 200L | D25: 1770 | F25: 0.932 | G25: 0.85 | H25: 274 | I25: 37 | J25: 65 | K25: 65 | L25: 50-63 | M25: 37 | N25: 80 | O25: 80 | P25: 63-80 | Q25: 37 | R25: 150 | S25: 150 | T25: 100-150
A26: 45 | B26: 60 | C26: 225S/M | D26: 1780 | F26: 0.939 | G26: 0.86 | H26: 410 | I26: 45 | J26: 75 | K26: 80 | L26: 63-80 | M26: 45 | N26: 95 | O26: 95 | P26: 75-97 | Q26: 45 | R26: 150 | S26: 150 | T26: 100-150
A27: 55 | B27: 75 | C27: 225S/M | D27: 1775 | F27: 0.941 | G27: 0.88 | H27: 410 | I27: 55 | J27: 100 | K27: 95 | L27: 75-97 | M27: 55 | N27: 105 | O27: 105 | P27: 90-112 | Q27: 55 | R27: 185 | S27: 180 | T27: 140-215
A28: 75 | B28: 100 | C28: 250S/M | D28: 1785 | F28: 0.945 | G28: 0.85 | H28: 510 | I28: 75 | J28: 150 | K28: 150 | L28: 100-150 | M28: 75 | N28: 150 | O28: 150 | P28: 100-150 | Q28: 75 | R28: 250 | S28: 250 | T28: 200-310
A29: 90 | B29: 125 | C29: 280S/M | D29: 1785 | F29: 0.95 | G29: 0.85 | H29: 700 | I29: 90 | J29: 150 | K29: 150 | L29: 100-150 | M29: 90 | N29: 185 | O29: 180 | P29: 140-215 | Q29: 90 | R29: 320 | S29: 300 | T29: 200-310
A30: 110 | B30: 150 | C30: 280S/M | D30: 1785 | F30: 0.95 | G30: 0.86 | H30: 740 | I30: 110 | J30: 185 | K30: 180 | L30: 140-215 | M30: 110 | N30: 250 | O30: 250 | P30: 140-215 | Q30: 110 | R30: 420 | S30: 400 | T30: 275-420
A31: 132 | B31: 175 | C31: 315S/M | D31: 1785 | F31: 0.95 | G31: 0.87 | H31: 841 | I31: 132 | J31: 250 | K31: 250 | L31: 200-310 | M31: 132 | N31: 250 | O31: 250 | P31: 200-310 | Q31: 132 | R31: 420 | S31: 500 | T31: 400-600
A32: 150 | B32: 200 | C32: 280S/M | D32: 1785 | F32: 0.955 | G32: 0.87 | H32: 868 | I32: 150 | J32: 250 | K32: 250 | L32: 200-310 | M32: 150 | N32: 320 | O32: 300 | P32: 200-310 | Q32: 150 | R32: 500 | S32: 500 | T32: 400-600
A33: 185 | B33: 250 | C33: 315S/M | D33: 1785 | F33: 0.955 | G33: 0.86 | H33: 1005 | I33: 185 | J33: 320 | K33: 300 | L33: 200-310 | M33: 185 | N33: 420 | O33: 400 | P33: 275-420 | Q33: 185 | R33: 700 | S33: 630 | T33: 560-840
A34: 220 | B34: 300 | C34: 355M/L | D34: 1790 | F34: 0.955 | G34: 0.87 | H34: 1349 | I34: 220 | J34: 420 | K34: 400 | L34: 275-420 | M34: 220 | N34: 420 | O34: 400 | P34: 275-420 | Q34: 220 | R34: 700 | S34: 800 | T34: 560-840
A35: 260 | B35: 350 | C35: 355M/L | D35: 1790 | F35: 0.96 | G35: 0.87 | H35: 1488 | I35: 260 | J35: 420 | K35: 500 | L35: 275-420 | M35: 260 | N35: 500 | O35: 500 | P35: 400-600 | Q35: 260 | R35: 1000 | S35: - | T35: 560-840
A36: 300 | B36: 400 | C36: 355M/L | D36: 1790 | F36: 0.959 | G36: 0.88 | H36: 1590 | I36: 300 | J36: 500 | K36: 500 | L36: 400-600 | M36: 300 | N36: 700 | O36: 630 | P36: 400-600 | Q36: 300 | R36: 1000 | S36: - | T36: -
A37: 330 | B37: 450 | C37: 355M/L | D37: 1790 | F37: 0.961 | G37: 0.88 | H37: 1702 | I37: 330 | J37: 700 | K37: 630 | L37: 400-600 | M37: 330 | N37: 700 | O37: 630 | P37: 560-840 | Q37: 330 | R37: - | S37: - | T37: -
A38: 370 | B38: 500 | C38: 355M/L* | D38: 1790 | F38: 0.962 | G38: 0.88 | H38: 1795 | I38: 370 | J38: 700 | K38: 630 | L38: 400-600 | M38: 370 | N38: 700 | O38: 800 | P38: 560-840 | Q38: 370 | R38: - | S38: - | T38: -

Sheet INSTALAÇÃO
